Workbook

Sheet Lakes of Oklahoma Data
A1: LAKE NAME | B1: YEAR BUILT | C1: AUTHORITY | D1: PLANNING REGION | E1: COUNTY | F1: Level III Ecoregion | G1: STREAM | H1: LATITUDE | I1: LONGITUDE | J1: NORMAL ELEVATION (ft) | K1: NORMAL AREA (ac) | L1: NORMAL CAPACITY (ac-ft) | M1: SHORELINE (mi) | N1: Max Depth (m) | O1: MAX DEPTH (ft) | P1: DESIGNATED BENEFICIAL USES* | Q1: Totol Phosphorus Ecoregional Threshold | R1: Total Nitrogent Ecoregional Threshold (based on DOC of 8.5) | S1: unit
A2: Hobart/Rocky | B2: 1933 | C2: City of Hobart | D2: Southwest | E2: Washita | F2: =VLOOKUP(E2,Sheet1!$A$1:$B$83,2) -> Central Great Plains | G2: Little Elk Creek | H2: 35.16619 | I2: -99.07131 | J2: 1634 | K2: 347 | L2: 4210 | M2: 8.4 | N2: =O2/3.28084 -> 3.1089599 | O2: 10.2 | P2: FW, R, WS | Q2: 59 | R2: 1000 | S2: ug
A3: Evan Chambers | B3: 1965 | C3: OK Dept. of Wildlife | D3: Panhandle | E3: Beaver | F3: Southwestern Tablelands | G3: Mexico Creek | H3: 36.72941 | I3: -100.21495 | J3: 2322 | K3: 89 | L3: 708 | M3: 3.5 | N3: =O3/3.28084 -> 3.3527999 | O3: 11 | P3: not available | Q3: 30 | R3: 770 | S3: ug
A4: Dave Boyer | B4: 1936 | C4: City of Walters | D4: Beaver-Cache | E4: Cotton | F4: =VLOOKUP(E4,Sheet1!$A$1:$B$83,2) -> Central Great Plains | G4: East Cache Creek Tributary | H4: 34.37268 | I4: -98.33157 | J4: 1012 | K4: 121 | L4: 936 | M4: 2.3 | N4: =O4/3.28084 -> 4.2062399 | O4: 13.8 | P4: FW, R, WS, AG, AES | Q4: 55 | R4: 1000 | S4: ug
A5: Taylor | B5: 1960 | C5: City of Marlow (leased) | D5: Lower Washita | E5: Grady | F5: =VLOOKUP(E5,Sheet1!$A$1:$B$83,2) -> Cross Timbers | G5: Rush Creek | H5: 34.75233 | I5: -97.92453 | J5: 1255 | K5: 227 | L5: 1877 | M5: 5.9 | N5: =O5/3.28084 -> 4.6939198 | O5: 15.4 | P5: FW, R, WS | Q5: 26 | R5: 760 | S5: ug
A6: Great Salt Plains | B6: 1941 | C6: Army Corps of Engineers | D6: Upper Arkansas | E6: Alfalfa | F6: Central Great Plains | G6: Salt Fork of the Arkansas River | H6: 36.74229 | I6: -98.13351 | J6: 1125 | K6: 8690 | L6: 13900 | M6: 25 | N6: =O6/3.28084 -> 4.8767998 | O6: 16 | P6: FW, R | Q6: 55 | R6: 1000 | S6: ug
A7: Tecumseh | B7: 1934 | C7: City of Tecumseh | D7: Central | E7: Pottawatomie | F7: Cross Timbers | G7: Squirrel Creek Tributary | H7: 35.28919 | I7: -96.95815 | J7: 1016 | K7: 127 | L7: 1118 | M7: 3.1 | N7: =O7/3.28084 -> 4.9072798 | O7: 16.1 | P7: FW, R, WS | Q7: 26 | R7: 760 | S7: ug
A8: Overholser | B8: 1919 | C8: City of Oklahoma City | D8: Central | E8: Oklahoma | F8: =VLOOKUP(E8,Sheet1!$A$1:$B$83,2) -> Central Great Plains | G8: North Canadian River | H8: 35.4852 | I8: -97.67012 | J8: 1241 | K8: 1581 | L8: 13526 | M8: 7.3 | N8: =O8/3.28084 -> 5.1511198 | O8: 16.9 | P8: FW, R, WS | Q8: 51 | R8: 1000 | S8: ug
A9: Elmer | B9: 1962 | C9: OK Dept. of Wildlife | D9: Central | E9: Kingfisher | F9: Central Great Plains | G9: Kingfisher Creek Tributary | H9: 35.8817 | I9: -97.98847 | J9: 1122 | K9: 37.9 | L9: 1080 | M9: 2.2 | N9: =O9/3.28084 -> 5.4863998 | O9: 18 | P9: not available | Q9: 51 | R9: 1000 | S9: ug
A10: Wiley Post Memorial | B10: 1971 | C10: City of Maysville | D10: Lower Washita | E10: McClain | F10: =VLOOKUP(E10,Sheet1!$A$1:$B$83,2) -> Central Great Plains | G10: Gaddis Creek | H10: 34.86571 | I10: -97.38562 | J10: 965 | K10: 302 | L10: 2082 | M10: 5.6 | N10: =O10/3.28084 -> 5.6083198 | O10: 18.4 | P10: FW, R, WS | Q10: 51 | R10: 1000 | S10: ug
A11: El Reno | B11: 1966 | C11: City of El Reno | D11: Central | E11: Canadian | F11: =VLOOKUP(E11,Sheet1!$A$1:$B$83,2) -> Central Great Plains | G11: Fourmile Creek | H11: 35.52301 | I11: -97.98681 | J11: 1363 | K11: 170 | L11: 709 | M11: 4.4 | N11: =O11/3.28084 -> 5.7911998 | O11: 19 | P11: AG, AES, FW, R | Q11: 51 | R11: 1000 | S11: ug
A12: Dahlgren | B12: 1953 | C12: OK Dept. of Wildlife | D12: Central | E12: Cleveland | F12: Central Great Plains | G12: Helsel Creek | H12: 35.05691 | I12: -97.19797 | J12: 1112 | K12: 22 | L12: 222 | M12: 1 | N12: =O12/3.28084 -> 5.7911998 | O12: 19 | P12: not available | Q12: 51 | R12: 1000 | S12: ug
A13: Hulah | B13: 1951 | C13: Army Corps of Engineers | D13: Middle Arkansas | E13: Osage | F13: =VLOOKUP(E13,Sheet1!$A$1:$B$83,2) -> Cross Timbers | G13: Caney River | H13: 36.93609 | I13: -96.07436 | J13: 733 | K13: 2635 | L13: 15968 | M13: 27.3 | N13: =O13/3.28084 -> 6.1569598 | O13: 20.2 | P13: FW, R, WS | Q13: 25 | R13: 760 | S13: ug
A14: Ozzie Cobb | B14: 1958 | C14: OK Dept. of Wildlife | D14: Southeast | E14: Pushmataha | F14: Ouachita Mountains | G14: Rock Creek | H14: 34.24477 | I14: -95.38522 | J14: 513 | K14: 58 | L14: 833 | M14: 3.1 | N14: =O14/3.28084 -> 6.7055998 | O14: 22 | P14: FW, R | Q14: 18 | R14: 600 | S14: ug
A15: Raymond Gary | B15: 1956 | C15: OK Dept. of Wildlife | D15: Southeast | E15: Choctaw | F15: South Central Plains | G15: Gates Creek | H15: 33.99407 | I15: -95.25602 | J15: 401 | K15: 263 | L15: 1681 | M15: 10.1 | N15: =O15/3.28084 -> 6.7055998 | O15: 22 | P15: FW, R, WS | Q15: 27 | R15: 530 | S15: ug
A16: Boomer | B16: 1932 | C16: City of Stillwater | D16: Upper Arkansas | E16: Payne | F16: =VLOOKUP(E16,Sheet1!$A$1:$B$83,2) -> Central Great Plains | G16: Boomer Creek | H16: 36.14721 | I16: -97.06769 | J16: 910 | K16: 223 | L16: 1484 | M16: 10.1 | N16: =O16/3.28084 -> 6.7360798 | O16: 22.1 | P16: AG, AES, FW, R, WS | Q16: 48 | R16: 1000 | S16: ug
A17: Guthrie | B17: 1919 | C17: City of Guthrie | D17: Central | E17: Logan | F17: =VLOOKUP(E17,Sheet1!$A$1:$B$83,2) -> Central Great Plains | G17: Cottonwood Creek Tributary | H17: 35.81605 | I17: -97.44281 | J17: 982 | K17: 205 | L17: 2403 | M17: 5.1 | N17: =O17/3.28084 -> 6.8579998 | O17: 22.5 | P17: FW, R, WS | Q17: 48 | R17: 1000 | S17: ug
A18: New Spiro | B18: 1960 | C18: Town of Spiro | D18: Lower Arkansas | E18: LeFlore | F18: =VLOOKUP(E18,Sheet1!$A$1:$B$83,2) -> Arkansas Valley | G18: Holi-Tuska Creek | H18: 35.19649 | I18: -94.61557 | J18: 426 | K18: 250 | L18: 2023 | M18: 5.8 | N18: =O18/3.28084 -> 6.9189598 | O18: 22.7 | P18: FW, R, WS | Q18: 24 | R18: 640 | S18: ug
A19: Tom Steed | B19: 1975 | C19: Bureau of Reclamation | D19: Southwest | E19: Kiowa | F19: =VLOOKUP(E19,Sheet1!$A$1:$B$83,2) -> Central Great Plains | G19: West Otter Creek | H19: 34.74655 | I19: -98.96917 | J19: 1411 | K19: 6400 | L19: 88970 | M19: 29.7 | N19: =O19/3.28084 -> 7.1932798 | O19: 23.6 | P19: FW, R | Q19: 48 | R19: 1000 | S19: ug
A20: Purcell | B20: 1930 | C20: City of Purcell | D20: Central | E20: McClain | F20: =VLOOKUP(E20,Sheet1!$A$1:$B$83,2) -> Central Great Plains | G20: Walnut Creek Tributary | H20: 34.98876 | I20: -97.37874 | J20: 1068 | K20: 157 | L20: 2600 | M20: 4.5 | N20: =O20/3.28084 -> 7.3151998 | O20: 24 | P20: not available | Q20: 48 | R20: 1000 | S20: ug
A21: Meeker | B21: 1970 | C21: City of Meeker | D21: Central | E21: Lincoln | F21: Cross Timbers | G21: South Quapaw Creek | H21: 35.49333 | I21: -96.93685 | J21: 908 | K21: 211 | L21: 1962 | M21: 4.9 | N21: =O21/3.28084 -> 7.3761598 | O21: 24.2 | P21: FW, R, WS | Q21: 24 | R21: 760 | S21: ug
A22: Elk City | B22: 1970 | C22: City of Elk City | D22: Southwest | E22: Beckham | F22: =VLOOKUP(E22,Sheet1!$A$1:$B$83,2) -> Central Great Plains | G22: West Elk Creek | H22: 35.36536 | I22: -99.41452 | J22: 1891 | K22: 240 | L22: 2583 | M22: 6 | N22: =O22/3.28084 -> 7.4066398 | O22: 24.3 | P22: FW, R | Q22: 48 | R22: 1000 | S22: ug
A23: Pawnee | B23: 1932 | C23: City of Pawnee | D23: Upper Arkansas | E23: Pawnee | F23: =VLOOKUP(E23,Sheet1!$A$1:$B$83,2) -> Central Great Plains | G23: Skedee Creek | H23: 36.35737 | I23: -96.80806 | J23: 867 | K23: 310 | L23: 3533 | M23: 5.4 | N23: =O23/3.28084 -> 7.4066398 | O23: 24.3 | P23: FW, R, WS | Q23: 48 | R23: 1000 | S23: ug
A24: Claremore | B24: 1930 | C24: City of Claremore | D24: Middle Arkansas | E24: Rogers | F24: =VLOOKUP(E24,Sheet1!$A$1:$B$83,2) -> Central Irregular Plains | G24: Dog Creek | H24: 36.33027 | I24: -95.58189 | J24: 610 | K24: 621 | L24: 5188 | M24: 17.8 | N24: =O24/3.28084 -> 7.4066398 | O24: 24.3 | P24: AG, AES, FW, R, WS | Q24: 28 | R24: 780 | S24: ug
A25: Wetumka | B25: 1939 | C25: City of Wetumka | D25: Central | E25: Hughes | F25: =VLOOKUP(E25,Sheet1!$A$1:$B$83,2) -> Cross Timbers | G25: North Canadian River Tributary | H25: 35.28289 | I25: -96.25128 | J25: 742 | K25: 169 | L25: 1839 | M25: 5.9 | N25: =O25/3.28084 -> 7.4066398 | O25: 24.3 | P25: FW, R, WS | Q25: 24 | R25: 760 | S25: ug
A26: Vanderwork | B26: 1968 | C26: OK Dept. of Wildlife | D26: West Central | E26: Washita | F26: =VLOOKUP(E26,Sheet1!$A$1:$B$83,2) -> Central Great Plains | G26: Gyp Creek | H26: 35.16263 | I26: -98.82478 | J26: 1440 | K26: 135 | L26: 1578 | M26: 5.6 | N26: =O26/3.28084 -> 7.6199998 | O26: 25 | P26: not available | Q26: 48 | R26: 1000 | S26: ug
A27: Nanih Waiya | B27: 1958 | C27: OK Dept. of Wildlife | D27: Southeast | E27: Pushmataha | F27: Ouachita Mountains | G27: Kiamichi River Tributary | H27: 34.63246 | I27: -95.29761 | J27: 594 | K27: 104 | L27: 1064 | M27: 2.4 | N27: =O27/3.28084 -> 7.6199998 | O27: 25 | P27: FW, R | Q27: 18 | R27: 600 | S27: ug
A28: Schooler | B28: 1955 | C28: OK Dept. of Wildlife | D28: Southeast | E28: Choctaw | F28: South Central Plains | G28: South Fork Holly Creek | H28: 34.10446 | I28: -95.37149 | J28: 492 | K28: 22.6 | L28: 306 | M28: 1.4 | N28: =O28/3.28084 -> 7.6199998 | O28: 25 | P28: FW, R, WS | Q28: 27 | R28: 530 | S28: ug
A29: Duncan | B29: 1937 | C29: City of Duncan | D29: Lower Washita | E29: Stephens | F29: =VLOOKUP(E29,Sheet1!$A$1:$B$83,2) -> Cross Timbers | G29: Fitzpatrick Creek | H29: 34.5256 | I29: -97.81326 | J29: 1082 | K29: 500 | L29: 7200 | M29: 5.9 | N29: =O29/3.28084 -> 7.7114398 | O29: 25.3 | P29: FW, R, WS, AG, AES | Q29: 24 | R29: 760 | S29: ug
A30: Watonga | B30: 1955 | C30: OK Dept of Wildlife | D30: Central | E30: Blaine | F30: Central Great Plains | G30: Bitter Creek | H30: 35.94345 | I30: -98.42365 | J30: 1373 | K30: 55 | L30: 656 | M30: 2.5 | N30: =O30/3.28084 -> 7.9247997 | O30: 26 | P30: FW, R, WS | Q30: 48 | R30: 1000 | S30: ug
A31: Chandler | B31: 1954 | C31: City of Chandler | D31: Central | E31: Lincoln | F31: Cross Timbers | G31: Bellcalf Creek | H31: 35.73703 | I31: -96.91081 | J31: 892 | K31: 178 | L31: 2131 | M31: 4.2 | N31: =O31/3.28084 -> 7.9552797 | O31: 26.1 | P31: AG, AES, FW, R, WS | Q31: 24 | R31: 760 | S31: ug
A32: Liberty | B32: 1948 | C32: City of Guthrie | D32: Central | E32: Logan | F32: =VLOOKUP(E32,Sheet1!$A$1:$B$83,2) -> Central Great Plains | G32: Cottonwood Creek Tributary | H32: 35.80337 | I32: -97.46421 | J32: 992 | K32: 197 | L32: 2471 | M32: 4.8 | N32: =O32/3.28084 -> 7.9857597 | O32: 26.2 | P32: FW, R, WS | Q32: 48 | R32: 1000 | S32: ug
A33: Crowder | B33: 1959 | C33: State of OK (operated) | D33: West Central | E33: Washita | F33: =VLOOKUP(E33,Sheet1!$A$1:$B$83,2) -> Central Great Plains | G33: Cobb Creek | H33: 35.40071 | I33: -98.7007 | J33: 1520 | K33: 142 | L33: 1647 | M33: 8.2 | N33: =O33/3.28084 -> 7.9857597 | O33: 26.2 | P33: FW, R, WS, AG, AES | Q33: 48 | R33: 1000 | S33: ug
A34: Chickasha | B34: 1958 | C34: City of Chickasha | D34: Lower Washita | E34: Caddo | F34: =VLOOKUP(E34,Sheet1!$A$1:$B$83,2) -> Central Great Plains | G34: Spring Creek | H34: 35.14707 | I34: -98.13037 | J34: 1180 | K34: 1407 | L34: 17244 | M34: 12.2 | N34: =O34/3.28084 -> 8.1991197 | O34: 26.9 | P34: AG, AES, FW, R, WS | Q34: 45 | R34: 1000 | S34: ug
A35: Carter | B35: 1960 | C35: City of Madill | D35: Lower Washita | E35: Marshall | F35: Cross Timbers | G35: Glasses Creek Tributary | H35: 34.12464 | I35: -96.7954 | J35: 831 | K35: 85 | L35: 950 | M35: 3.1 | N35: =O35/3.28084 -> 8.1991197 | O35: 26.9 | P35: AG, AES, FW, R, WS | Q35: 23 | R35: 760 | S35: ug
A36: Wewoka | B36: 1925 | C36: City of Wewoka | D36: Eufaula | E36: Seminole | F36: =VLOOKUP(E36,Sheet1!$A$1:$B$83,2) -> Cross Timbers | G36: Coon Creek | H36: 35.18065 | I36: -96.52299 | J36: 827 | K36: 371 | L36: 3301 | M36: 9.9 | N36: =O36/3.28084 -> 8.2905597 | O36: 27.2 | P36: FW, R, WS | Q36: 23 | R36: 760 | S36: ug
A37: Clinton | B37: 1931 | C37: City of Clinton | D37: West Central | E37: Washita | F37: =VLOOKUP(E37,Sheet1!$A$1:$B$83,2) -> Central Great Plains | G37: Turkey Creek | H37: 35.4322 | I37: -99.21802 | J37: 1730 | K37: 283 | L37: 3140 | M37: 7.7 | N37: =O37/3.28084 -> 8.3210397 | O37: 27.3 | P37: AG, AES, FW, R, WS | Q37: 45 | R37: 1000 | S37: ug
A38: Prague | B38: 1984 | C38: City of Prague | D38: Central | E38: Lincoln | F38: Cross Timbers | G38: Sand Creek | H38: 35.52407 | I38: -96.7244 | J38: 868 | K38: 225 | L38: 2415 | M38: 5.7 | N38: =O38/3.28084 -> 8.4124797 | O38: 27.6 | P38: FW, R | Q38: 23 | R38: 760 | S38: ug
A39: Hall | B39: 1954 | C39: OK Dept. of Wildlife | D39: Southwest | E39: Harmon | F39: =VLOOKUP(E39,Sheet1!$A$1:$B$83,2) -> Central Great Plains | G39: Salt Fork of the Red River Tributary | H39: 34.83151 | I39: -99.92447 | J39: 1804 | K39: 35.7 | L39: 560 | M39: 1.6 | N39: =O39/3.28084 -> 8.8391997 | O39: 29 | P39: not available | Q39: 45 | R39: 1000 | S39: ug
A40: Burtschi | B40: 1954 | C40: OK Dept. of Wildlife | D40: Lower Washita | E40: Grady | F40: =VLOOKUP(E40,Sheet1!$A$1:$B$83,2) -> Cross Timbers | G40: East Bills Creek | H40: 34.967 | I40: -98.06392 | J40: 1207 | K40: 168 | L40: 2140 | M40: 3.9 | N40: =O40/3.28084 -> 8.8391997 | O40: 29 | P40: AG, AES, FW, R | Q40: 23 | R40: 760 | S40: ug
...

Sheet Sheet2
A1: county | B1: match
A2: Adair | B2: =MATCH(A2,Sheet1!A:A,0) -> 2
A3: Alfalfa | B3: =MATCH(A3,Sheet1!A:A,0) -> 3
A4: Atoka | B4: =MATCH(A4,Sheet1!A:A,0) -> 4
A5: Beaver | B5: =MATCH(A5,Sheet1!A:A,0) -> 5
A6: Beckham | B6: =MATCH(A6,Sheet1!A:A,0) -> 6
A7: Blaine | B7: =MATCH(A7,Sheet1!A:A,0) -> 7
A8: Bryan | B8: =MATCH(A8,Sheet1!A:A,0) -> 8
A9: Caddo | B9: =MATCH(A9,Sheet1!A:A,0) -> 9
A10: Canadian | B10: =MATCH(A10,Sheet1!A:A,0) -> 10
A11: Carter | B11: =MATCH(A11,Sheet1!A:A,0) -> 11
A12: Cherokee | B12: =MATCH(A12,Sheet1!A:A,0) -> 12
A13: Choctaw | B13: =MATCH(A13,Sheet1!A:A,0) -> 13
... A78: Woodward | B78: =MATCH(A78,Sheet1!A:A,0) -> 83

Sheet Sheet1
A1: County | B1: Ecoregion III | C1: Ecoregion IV | D1: Match
A2: Adair | B2: No Assignment
A3: Alfalfa | B3: No Assignment
A4: Atoka | B4: No Assignment
A5: Beaver | B5: No Assignment
A6: Beckham | B6: Central Great Plains | C6: Rolling Red Hills | D6: =MATCH(A6,Sheet2!A:A,0) -> 6
A7: Blaine | B7: No Assignment
A8: Bryan | B8: No Assignment
A9: Caddo | B9: Central Great Plains | C9: Cross Timbers Transition | D9: =MATCH(A9,Sheet2!A:A,0) -> 9
A10: Canadian | B10: Central Great Plains | C10: Prairie Tableland | D10: =MATCH(A10,Sheet2!A:A,0) -> 10
A11: Carter | B11: Cross Timbers | C11: Arbuckle Mts | D11: =MATCH(A11,Sheet2!A:A,0) -> 11
A12: Cherokee | B12: Boston Mountains | C12: Lower Boston Mountains | D12: =MATCH(A12,Sheet2!A:A,0) -> 12
A13: Choctaw | B13: No Assignment
A14: Cimarron | B14: Southwestern Tablelands | C14: Mesa de Maya/Black Mesa | D14: =MATCH(A14,Sheet2!A:A,0) -> 14
A15: Cleveland | B15: No Assignment
A16: Coal | B16: Arkansas Valley | C16: Lower Canadian Hills | D16: =MATCH(A16,Sheet2!A:A,0) -> 16
A17: Coal | B17: Cross Timbers | C17: Arbuckle Uplift | D17: =MATCH(A17,Sheet2!A:A,0) -> 16
A18: Comanche | B18: No Assignment
A19: Cotton | B19: Central Great Plains | C19: Broken Red Plains | D19: =MATCH(A19,Sheet2!A:A,0) -> 18
A20: Craig | B20: No Assignment
A21: Creek | B21: Cross Timbers | C21: Northern Cross Timbers | D21: =MATCH(A21,Sheet2!A:A,0) -> 20
A22: Custer | B22: No Assignment
A23: Delaware | B23: No Assignment
A24: Dewey | B24: Central Great Plains | C24: Prairie Tableland | D24: =MATCH(A24,Sheet2!A:A,0) -> 23
A25: Ellis | B25: Southwestern Tablelands | C25: Cimmarron/Canadian Breaks | D25: =MATCH(A25,Sheet2!A:A,0) -> 24
A26: Garfield | B26: No Assignment
A27: Garvin | B27: No Assignment
A28: Grady | B28: Cross Timbers | C28: Northern Cross Timbers | D28: =MATCH(A28,Sheet2!A:A,0) -> 27
A29: Grant | B29: No Assignment
A30: Greer | B30: No Assignment
A31: Harmon | B31: Central Great Plains | C31: Red River Tablelands | D31: =MATCH(A31,Sheet2!A:A,0) -> 30
A32: Harper | B32: No Assignment
A33: Haskell | B33: No Assignment
A34: Hughes | B34: Cross Timbers | C34: Northern Cross Timbers | D34: =MATCH(A34,Sheet2!A:A,0) -> 33
A35: Jackson | B35: No Assignment
A36: Jefferson | B36: No Assignment
A37: Johnston | B37: No Assignment
A38: Kay | B38: Flint Hills | C38: Flint Hills | D38: =MATCH(A38,Sheet2!A:A,0) -> 37
A39: Kay | B39: Central Great Plains | C39: Prairie Tableland | D39: =MATCH(A39,Sheet2!A:A,0) -> 37
A40: Kingfisher | B40: No Assignment
...
